2025-10-29 22:53:03,115 - ERROR - Task exception was never retrieved
future: <Task finished name='Task-31' coro=<WebSocketProtocol13.write_message.<locals>.wrapper() done, defined at C:\Users\ACER\AppData\Roaming\Python\Python312\site-packages\tornado\websocket.py:1086> exception=WebSocketClosedError()>
Traceback (most recent call last):
  File "C:\Users\ACER\AppData\Roaming\Python\Python312\site-packages\streamlit\web\bootstrap.py", line 348, in run
    if asyncio.get_running_loop().is_running():
       ^^^^^^^^^^^^^^^^^^^^^^^^^^
RuntimeError: no running event loop

During handling of the above exception, another exception occurred:

Traceback (most recent call last):
  File "C:\Users\ACER\AppData\Roaming\Python\Python312\site-packages\tornado\websocket.py", line 1088, in wrapper
    await fut
tornado.iostream.StreamClosedError: Stream is closed

During handling of the above exception, another exception occurred:

Traceback (most recent call last):
  File "C:\Users\ACER\AppData\Roaming\Python\Python312\site-packages\tornado\websocket.py", line 1090, in wrapper
    raise WebSocketClosedError()
tornado.websocket.WebSocketClosedError
